Workbook

Sheet Sheet1
A1: 流程
A2: 流程 | B2: 数据库 | C2: 表 | D2: 描述 | E2: 备注 | F2: nn | G2: csyy | H2: mxd | I2: dfd | J2: unifi | K2: maiya
A3: 短信验证 | B3: db_nono | C3: system_sms_log | D3: 短信发送日志表 | F3: 1 | G3: 0 | H3: 1 | I3: 1 | J3: 1 | K3: 0
A4: 短信验证 | B4: db_nono | C4: sms_channel_info | D4: 短信通道维表 | F4: 1 | G4: 0 | H4: 1 | I4: 1 | J4: 1 | K4: 0
A5: 短信验证 | B5: db_nono | C5: sms_task | D5: 后台定时短信任务 | F5: 1 | G5: 0 | H5: 1 | I5: 1 | J5: 1 | K5: 0
A6: 短信验证 | B6: db_nono | C6: sms_task_detail | D6: 后台定时短信任务明细 | F6: 1 | G6: 0 | H6: 1 | I6: 1 | J6: 1 | K6: 0
A7: 用户注册 | B7: db_nono | C7: user_info | D7: 用户基本信息 | F7: 1 | G7: 1 | H7: 1 | I7: 1 | J7: 1 | K7: 1
A8: 用户注册 | B8: db_nono | C8: user_info_detail | D8: 用户详细信息
A9: 促销

Sheet Sheet3
A1: 数据库 | B1: 表名 | C1: 表格描述 | D1: 行数 | E1: 创建时间 | F1: 人工备注 | G1: 新增行数
A2: db_nono | B2: InterestrateCut_template | C2: 减息券的模板 | D2: 62 | E2: 42315.694 | F2: 减息券的模板 | G2: -1
A3: db_nono | B3: MGT_ORG | D3: 0 | E3: 42185.93 | G3: 0
A4: db_nono | B4: MGT_RESOURCE | D4: 16 | E4: 42185.931 | G4: 0
A5: db_nono | B5: MGT_ROLE | D5: 3 | E5: 42185.931 | G5: 0
A6: db_nono | B6: MGT_ROLE_RESOURCE | D6: 9 | E6: 42185.931 | G6: 0
A7: db_nono | B7: MGT_USER | D7: 85 | E7: 42185.931 | G7: 0
A8: db_nono | B8: MGT_USER_ROLE | D8: 15 | E8: 42185.931 | G8: 0
A9: db_nono | B9: QRTZ_BLOB_TRIGGERS | D9: 0 | E9: 42185.932 | G9: 0
A10: db_nono | B10: QRTZ_CALENDARS | D10: 0 | E10: 42185.932 | G10: 0
A11: db_nono | B11: QRTZ_CRON_TRIGGERS | D11: 6 | E11: 42185.932 | G11: 0
A12: db_nono | B12: QRTZ_FIRED_TRIGGERS | D12: 1 | E12: 42185.932 | G12: 1
A13: db_nono | B13: QRTZ_JOB_DETAILS | D13: 6 | E13: 42185.932 | G13: 0
A14: db_nono | B14: QRTZ_LOCKS | D14: 2 | E14: 42185.932 | G14: 0
... A20: db_nono | B20: SCHEDULE_JOB | D20: 6 | E20: 42185.932 | G20: 0
A21: db_nono | B21: WeiXin_Qr_Code | C21: 微信二维码 | D21: 32 | E21: 42174.735 | F21: 微信二维码 | G21: 0
A22: db_nono | B22: account_relation | D22: 1896118 | E22: 42326.969 | G22: -25163
A23: db_nono | B23: action_log | C23: 操作日志表 | D23: 619046 | E23: 42247.784 | F23: 操作日志表 | G23: -567
A24: db_nono | B24: activity | C24: 活动表 | D24: 10 | E24: 42080.382 | F24: 活动表 | G24: 0
A25: db_nono | B25: activity_access_log | C25: 活动日志表 | D25: 3646 | E25: 42080.382 | F25: 财运活动表 | G25: 0
A26: db_nono | B26: activity_begging | D26: 31100 | E26: 42140.414 | G26: 0
A27: db_nono | B27: activity_begging_details | D27: 39828 | E27: 42140.415 | G27: 0
A28: db_nono | B28: activity_goods | C28: 活动商品表 | D28: 8 | E28: 42502.66 | F28: 活动商品表 | G28: 0
A29: db_nono | B29: activity_goods_log | C29: 商品库存修改记录表 | D29: 9 | E29: 42502.66 | F29: 商品库存修改记录表 | G29: 0
A30: db_nono | B30: activity_interest | C30: 活动收益表 | D30: 693 | E30: 42080.382 | F30: 大房东加息结果 | G30: 0
A31: db_nono | B31: activity_interest_details | C31: 活动收益详细信息表 | D31: 4042 | E31: 42080.382 | F31: 大房东加息详情 | G31: 0
A32: db_nono | B32: activity_interest_topic | C32: 活动页猜你感兴趣话题 | D32: 0 | E32: 42156.142 | F32: 活动页猜你感兴趣话题 | G32: 0
A33: db_nono | B33: activity_messages | C33: 活动消息表 | D33: 6019711 | E33: 42080.382 | F33: 每月精选收益短信发送记录 | G33: -113314
A34: db_nono | B34: activity_mobiles | C34: 活动手机号表 | D34: 3434997 | E34: 42080.382 | F34: 手机验证发送注册页 | G34: -28833
A35: db_nono | B35: activity_nbparty_user_info | D35: 41625 | E35: 42527.806 | G35: 0
A36: db_nono | B36: activity_point_log | D36: 7900826 | E36: 42331.622 | G36: -241467
A37: db_nono | B37: activity_point_log_back | D37: 32817272 | E37: 42499.666 | G37: 0
A38: db_nono | B38: activity_prize_gain_list | D38: 7340813 | E38: 42166.408 | G38: -214264
A39: db_nono | B39: activity_prize_gain_list_back | D39: 27192697 | E39: 42499.686 | G39: 0
A40: db_nono | B40: activity_prize_list | C40: 活动送礼表 | D40: 118 | E40: 42166.408 | F40: 活动送礼表 | G40: 0
A41: db_nono | B41: activity_prolocutor | C41: 镑客大使表(原表名prolocutor) | D41: 409479 | E41: 42156.142 | F41: 镑客大使表(原表名prolocutor) | G41: -1326
A42: db_nono | B42: activity_prolocutor_code | D42: 274209 | E42: 42192.655 | G42: -965
A43: db_nono | B43: activity_prolocutor_data | C43: 镑客大使数据表(原表名prolocutor_data) | D43: 0 | E43: 42156.142 | F43: 镑客大使数据表(原表名prolocutor_data) | G43: 0
A44: db_nono | B44: activity_red_packet | C44: 红包记录表 | D44: 66160 | E44: 42395.776 | F44: 红包记录表 | G44: 0
A45: db_nono | B45: activity_red_packet_gain_log | C45: 红包领取记录表 | D45: 968142 | E45: 42395.776 | F45: 红包领取记录表 | G45: 0
...

Sheet 业务流程 (2)
A4: 验证 | B4: 注册 | C4: 认证 | D4: 登录 | E4: 充值 | F4: 投资产品 | G4: 投资订单 | H4: 账户 | I4: 投资兑付 | J4: 提现 | K4: 券 | L4: 活动 | M4: 维表
A5: activity_mobiles | B5: user_info | C5: pengyuan_recharge_log | D5: user_action_log | E5: bill_recharges | F5: csyy_plan | G5: borrows_bidding | H5: finance_account | I5: vip_account | J5: withdraw_cash | K5: bank_code | L5: activity_vip | M5: america_school
A6: sms_channel_info | B6: user_info_detail | C6: user_bankcard_auth | D6: user_login_info | E6: kuaiq_orders | F6: debt_batch | G6: debt_buy_log | H6: fund_account | I6: fund_redeem_form | J6: withdraw_cash_alipay | K6: coupon_use | L6: activity_vip_label | M6: channel
A7: system_sms_log | B7: user_approach_info | C7: user_bankcard_info | E7: kuaiq_recharge_logs | F7: debt_sale | G7: vip_form | H7: vip_account | I7: borrows_accept | K7: unifi_InterestrateCut | L7: activity_vip_physicalgoods | M7: county_idnum_list
A8: system_voice_verify_log | B8: user_student_info | C8: nono_studentAuth_log | E8: online_recharge | F8: finance_plan | G8: fund_form | H8: finance_log | I8: debt_accept | K8: user_InterestrateCut | L8: activity_vip_physicalgoods_info | M8: region
B9: user_level | C9: nono_authentication | E9: recharge_log | F9: finance_plan_scope | G9: debt_buy_relation_log | H9: finance_operation | K9: user_coupon | L9: activity_vip_praise_log | M9: student_school
B10: user_spouse_info | C10: authentication_htsb | E10: sft_recharges | F10: invt_finance_plan_stage_info | G10: lazy_add | H10: finance_operation_relation | K10: user_hkconpon | L10: activity_vip_virtualgoods | M10: bank_info
B11: user_work_info | C11: borrows_archive | E11: yilian_orders | F11: invt_stage_debt_match | G11: debt_batch_buy_log | H11: finance_role | K11: user_experience_cash_log | L11: activity_point_log | M11: admin
B12: newborn_student_info | C12: mxd_score_result | E12: yilian_recharges | F12: invt_stage_debt_package | K12: user_experience_earnings_log | L12: activity_prize_gain_list
B13: user_company_info | C13: sesame_credit | E13: tb_pay_record | F13: invt_stage_lock_change_log | L13: activity_prize_list
B14: account_relation | C14: user_htsb_info | E14: tb_pay_record_log | F14: invt_user_debts_changes_log
C15: user_credit_investigation
C16: user_credit_rating_info
C17: face_beyond_result
C18: credit_user_htsb_info
F19: 贷款产品 | G19: 贷款订单 | I19: 贷后
F20: products | G20: borrows_loan | I20: borrows_outsource_dunning
F21: bill | G21: borrows_prepare | I21: black_gray_list
F22: bill_repayment_history | G22: borrows | I22: black_gray_rule
F23: credit_account | G23: borrows_consulted_fee
F24: credit_consume_log
G26: user_csmFinInfo
G27: borrows
G28: products
G29: borrows_guarantee
G30: borrows_repayment
G31: borrows_dunning_contact
G32: borrows_loan
G33: admin_work_remark
G34: borrows_raise
G35: borrows_prepare
G36: borrows_consulted_fee

Sheet 数据表
A1: 数据库 | B1: 流程 | C1: 表名 | D1: 表格描述 | E1: 行数 | F1: 创建时间 | G1: 人工备注 | H1: 新增行数
A2: db_nono | C2: InterestrateCut_template | D2: 减息券的模板 | E2: 62 | F2: 42315.694 | G2: 减息券的模板 | H2: -1
A3: db_nono | C3: MGT_RESOURCE | E3: 16 | F3: 42185.931 | H3: 0
A4: db_nono | C4: MGT_ROLE | E4: 3 | F4: 42185.931 | H4: 0
A5: db_nono | C5: MGT_ROLE_RESOURCE | E5: 9 | F5: 42185.931 | H5: 0
A6: db_nono | C6: MGT_USER | E6: 85 | F6: 42185.931 | H6: 0
A7: db_nono | C7: MGT_USER_ROLE | E7: 15 | F7: 42185.931 | H7: 0
A8: db_nono | C8: QRTZ_CRON_TRIGGERS | E8: 6 | F8: 42185.932 | H8: 0
A9: db_nono | C9: QRTZ_FIRED_TRIGGERS | E9: 1 | F9: 42185.932 | H9: 1
A10: db_nono | C10: QRTZ_JOB_DETAILS | E10: 6 | F10: 42185.932 | H10: 0
A11: db_nono | C11: QRTZ_LOCKS | E11: 2 | F11: 42185.932 | H11: 0
A12: db_nono | C12: QRTZ_SCHEDULER_STATE | E12: 1 | F12: 42185.932 | H12: 0
A13: db_nono | C13: QRTZ_TRIGGERS | E13: 6 | F13: 42185.932 | H13: 0
A14: db_nono | C14: SCHEDULE_JOB | E14: 6 | F14: 42185.932 | H14: 0
A15: db_nono | C15: WeiXin_Qr_Code | D15: 微信二维码 | E15: 32 | F15: 42174.735 | G15: 微信二维码 | H15: 0
A16: db_nono | B16: 0元付 | C16: bill | D16: 账单表，计算所有人的账单 | E16: 43737 | F16: 42169.413 | G16: 账单表，计算所有人的账单 | H16: 0
A17: db_nono | C17: action_log | D17: 操作日志表 | E17: 619046 | F17: 42247.784 | G17: 操作日志表 | H17: -567
A18: db_nono | C18: activity | D18: 活动表 | E18: 10 | F18: 42080.382 | G18: 活动表 | H18: 0
A19: db_nono | C19: activity_access_log | D19: 活动日志表 | E19: 3646 | F19: 42080.382 | G19: 财运活动表 | H19: 0
A20: db_nono | C20: activity_begging | E20: 31100 | F20: 42140.414 | H20: 0
A21: db_nono | C21: activity_begging_details | E21: 39828 | F21: 42140.415 | H21: 0
A22: db_nono | C22: activity_goods | D22: 活动商品表 | E22: 8 | F22: 42502.66 | G22: 活动商品表 | H22: 0
A23: db_nono | C23: activity_goods_log | D23: 商品库存修改记录表 | E23: 9 | F23: 42502.66 | G23: 商品库存修改记录表 | H23: 0
A24: db_nono | C24: activity_interest | D24: 活动收益表 | E24: 693 | F24: 42080.382 | G24: 大房东加息结果 | H24: 0
A25: db_nono | C25: activity_interest_details | D25: 活动收益详细信息表 | E25: 4042 | F25: 42080.382 | G25: 大房东加息详情 | H25: 0
A26: db_nono | C26: activity_messages | D26: 活动消息表 | E26: 6019711 | F26: 42080.382 | G26: 每月精选收益短信发送记录 | H26: -113314
A27: db_nono | B27: 0元付 | C27: bill_repayment_history | D27: 账单还款记录表，每还一次款会在这里生成一条记录 | E27: 7408 | F27: 42169.413 | G27: 账单还款记录表，每还一次款会在这里生成一条记录 | H27: -16
A28: db_nono | C28: activity_nbparty_user_info | E28: 41625 | F28: 42527.806 | H28: 0
A29: db_nono | B29: 0元付 | C29: credit_account | D29: 信用账户表 | E29: 8028 | F29: 42169.413 | G29: 信用账户表 | H29: -39
A30: db_nono | C30: activity_point_log_back | E30: 32817272 | F30: 42499.666 | H30: 0
A31: db_nono | B31: 0元付 | C31: credit_consume_log | D31: 信用消费记录表 | E31: 149255 | F31: 42169.413 | G31: 信用消费记录表 | H31: -147
A32: db_nono | C32: activity_prize_gain_list_back | E32: 27192697 | F32: 42499.686 | H32: 0
A33: db_nono | B33: 镑客大使邀请 | C33: activity_prolocutor | D33: 镑客大使表(原表名prolocutor) | E33: 409479 | F33: 42156.142 | G33: 镑客大使表(原表名prolocutor) | H33: -1326
A34: db_nono | B34: 充值 | C34: bill_recharges | D34: 快钱充值流水记录表 | E34: 183312 | F34: 42080.382 | G34: 快钱充值流水记录表 | H34: 0
A35: db_nono | C35: activity_prolocutor_code | E35: 274209 | F35: 42192.655 | H35: -965
A36: db_nono | C36: activity_red_packet | D36: 红包记录表 | E36: 66160 | F36: 42395.776 | G36: 红包记录表 | H36: 0
A37: db_nono | C37: activity_red_packet_gain_log | D37: 红包领取记录表 | E37: 968142 | F37: 42395.776 | G37: 红包领取记录表 | H37: 0
A38: db_nono | C38: activity_red_packet_resend_log | D38: 红包复发记录表 | E38: 37037 | F38: 42395.776 | G38: 红包复发记录表 | H38: 0
A39: db_nono | C39: activity_redrain | D39: 红包雨表 | E39: 3670 | F39: 42097.771 | G39: 客户获取红包总表 | H39: 0
A40: db_nono | C40: activity_redrain_details | D40: 红包雨详细信息表 | E40: 3639 | F40: 42097.771 | G40: 客户获取红包详情表 | H40: 0
...

Sheet 业务流程
A1: 诺诺、名校贷、大房东、unifi | C1: 财神爷爷 | E1: 麦芽分期 | G1: 诺诺、名校贷、大房东、unifi
A2: 类别/表名 | B2: 表描述 | C2: 类别/表名 | D2: 表描述 | E2: 类别/表名 | F2: 表描述 | G2: 类别/表名 | H2: 表描述
A3: 验证 | G3: 维表
A4: activity_mobiles | B4: =LEFT(IFERROR(VLOOKUP(A4,数据表!C:D,2,0),""),10) -> 活动手机号表 | D4: =LEFT(IFERROR(VLOOKUP(C4,数据表!C:D,2,0),""),10) | F4: =LEFT(IFERROR(VLOOKUP(E4,数据表!C:D,2,0),""),10) | G4: america_school | H4: =LEFT(IFERROR(VLOOKUP(G4,数据表!C:D,2,0),""),10) -> 美国学校信息表
A5: sms_channel_info | B5: =LEFT(IFERROR(VLOOKUP(A5,数据表!C:D,2,0),""),10) | D5: =LEFT(IFERROR(VLOOKUP(C5,数据表!C:D,2,0),""),10) | F5: =LEFT(IFERROR(VLOOKUP(E5,数据表!C:D,2,0),""),10) | G5: channel | H5: =LEFT(IFERROR(VLOOKUP(G5,数据表!C:D,2,0),""),10) -> 渠道表
A6: system_sms_log | B6: =LEFT(IFERROR(VLOOKUP(A6,数据表!C:D,2,0),""),10) -> 短信发送日志表 | D6: =LEFT(IFERROR(VLOOKUP(C6,数据表!C:D,2,0),""),10) | F6: =LEFT(IFERROR(VLOOKUP(E6,数据表!C:D,2,0),""),10) | G6: county_idnum_list | H6: =LEFT(IFERROR(VLOOKUP(G6,数据表!C:D,2,0),""),10) -> 区域身份证号码表
A7: system_voice_verify_log | B7: =LEFT(IFERROR(VLOOKUP(A7,数据表!C:D,2,0),""),10) -> 语音校验日志 | D7: =LEFT(IFERROR(VLOOKUP(C7,数据表!C:D,2,0),""),10) | F7: =LEFT(IFERROR(VLOOKUP(E7,数据表!C:D,2,0),""),10) | G7: region | H7: =LEFT(IFERROR(VLOOKUP(G7,数据表!C:D,2,0),""),10) -> 行政区划
B8: =LEFT(IFERROR(VLOOKUP(A8,数据表!C:D,2,0),""),10) | D8: =LEFT(IFERROR(VLOOKUP(C8,数据表!C:D,2,0),""),10) | F8: =LEFT(IFERROR(VLOOKUP(E8,数据表!C:D,2,0),""),10) | G8: student_school | H8: =LEFT(IFERROR(VLOOKUP(G8,数据表!C:D,2,0),""),10) -> 学校信息表
A9: 注册 | B9: =LEFT(IFERROR(VLOOKUP(A9,数据表!C:D,2,0),""),10) | D9: =LEFT(IFERROR(VLOOKUP(C9,数据表!C:D,2,0),""),10) | F9: =LEFT(IFERROR(VLOOKUP(E9,数据表!C:D,2,0),""),10) | G9: bank_info | H9: =LEFT(IFERROR(VLOOKUP(G9,数据表!C:D,2,0),""),10) -> 银行信息表(原表名b
A10: user_info | B10: =LEFT(IFERROR(VLOOKUP(A10,数据表!C:D,2,0),""),10) -> 用户基本信息 | C10: user | D10: =LEFT(IFERROR(VLOOKUP(C10,数据表!C:D,2,0),""),10) -> 会员信息表 | E10: ORD_USER | F10: =LEFT(IFERROR(VLOOKUP(E10,数据表!C:D,2,0),""),10) -> 借款用户基本信息表 | G10: admin | H10: =LEFT(IFERROR(VLOOKUP(G10,数据表!C:D,2,0),""),10) -> 管理员表
A11: user_info_detail | B11: =LEFT(IFERROR(VLOOKUP(A11,数据表!C:D,2,0),""),10) -> 用户详细信息 | C11: user_detail | D11: =LEFT(IFERROR(VLOOKUP(C11,数据表!C:D,2,0),""),10) -> 用户明细信息表 | E11: ORD_USER_DETAIL | F11: =LEFT(IFERROR(VLOOKUP(E11,数据表!C:D,2,0),""),10) -> 用户详情表 | H11: =LEFT(IFERROR(VLOOKUP(G11,数据表!C:D,2,0),""),10)
A12: user_approach_info | B12: =LEFT(IFERROR(VLOOKUP(A12,数据表!C:D,2,0),""),10) -> 用户渠道信息表 | C12: user_approach | D12: =LEFT(IFERROR(VLOOKUP(C12,数据表!C:D,2,0),""),10) | F12: =LEFT(IFERROR(VLOOKUP(E12,数据表!C:D,2,0),""),10) | H12: =LEFT(IFERROR(VLOOKUP(G12,数据表!C:D,2,0),""),10)
A13: user_student_info | B13: =LEFT(IFERROR(VLOOKUP(A13,数据表!C:D,2,0),""),10) -> 学生信息 | C13: user_relation | D13: =LEFT(IFERROR(VLOOKUP(C13,数据表!C:D,2,0),""),10) | F13: =LEFT(IFERROR(VLOOKUP(E13,数据表!C:D,2,0),""),10) | H13: =LEFT(IFERROR(VLOOKUP(G13,数据表!C:D,2,0),""),10)
A14: user_level | B14: =LEFT(IFERROR(VLOOKUP(A14,数据表!C:D,2,0),""),10) -> 会员等级表 | D14: =LEFT(IFERROR(VLOOKUP(C14,数据表!C:D,2,0),""),10) | F14: =LEFT(IFERROR(VLOOKUP(E14,数据表!C:D,2,0),""),10) | H14: =LEFT(IFERROR(VLOOKUP(G14,数据表!C:D,2,0),""),10)
A15: user_spouse_info | B15: =LEFT(IFERROR(VLOOKUP(A15,数据表!C:D,2,0),""),10) -> 用户配偶信息 | D15: =LEFT(IFERROR(VLOOKUP(C15,数据表!C:D,2,0),""),10) | F15: =LEFT(IFERROR(VLOOKUP(E15,数据表!C:D,2,0),""),10) | H15: =LEFT(IFERROR(VLOOKUP(G15,数据表!C:D,2,0),""),10)
A16: user_work_info | B16: =LEFT(IFERROR(VLOOKUP(A16,数据表!C:D,2,0),""),10) -> 用户工作信息 | D16: =LEFT(IFERROR(VLOOKUP(C16,数据表!C:D,2,0),""),10) | F16: =LEFT(IFERROR(VLOOKUP(E16,数据表!C:D,2,0),""),10) | H16: =LEFT(IFERROR(VLOOKUP(G16,数据表!C:D,2,0),""),10)
A17: newborn_student_info | B17: =LEFT(IFERROR(VLOOKUP(A17,数据表!C:D,2,0),""),10) | D17: =LEFT(IFERROR(VLOOKUP(C17,数据表!C:D,2,0),""),10) | F17: =LEFT(IFERROR(VLOOKUP(E17,数据表!C:D,2,0),""),10) | H17: =LEFT(IFERROR(VLOOKUP(G17,数据表!C:D,2,0),""),10)
A18: user_company_info | B18: =LEFT(IFERROR(VLOOKUP(A18,数据表!C:D,2,0),""),10) -> 用户公司信息表 | D18: =LEFT(IFERROR(VLOOKUP(C18,数据表!C:D,2,0),""),10) | F18: =LEFT(IFERROR(VLOOKUP(E18,数据表!C:D,2,0),""),10) | H18: =LEFT(IFERROR(VLOOKUP(G18,数据表!C:D,2,0),""),10)
A19: account_relation | B19: =LEFT(IFERROR(VLOOKUP(A19,数据表!C:D,2,0),""),10) | D19: =LEFT(IFERROR(VLOOKUP(C19,数据表!C:D,2,0),""),10) | F19: =LEFT(IFERROR(VLOOKUP(E19,数据表!C:D,2,0),""),10) | H19: =LEFT(IFERROR(VLOOKUP(G19,数据表!C:D,2,0),""),10)
B20: =LEFT(IFERROR(VLOOKUP(A20,数据表!C:D,2,0),""),10) | D20: =LEFT(IFERROR(VLOOKUP(C20,数据表!C:D,2,0),""),10) | F20: =LEFT(IFERROR(VLOOKUP(E20,数据表!C:D,2,0),""),10) | H20: =LEFT(IFERROR(VLOOKUP(G20,数据表!C:D,2,0),""),10)
A21: 认证 | B21: =LEFT(IFERROR(VLOOKUP(A21,数据表!C:D,2,0),""),10) | D21: =LEFT(IFERROR(VLOOKUP(C21,数据表!C:D,2,0),""),10) | F21: =LEFT(IFERROR(VLOOKUP(E21,数据表!C:D,2,0),""),10) | H21: =LEFT(IFERROR(VLOOKUP(G21,数据表!C:D,2,0),""),10)
A22: pengyuan_recharge_log | B22: =LEFT(IFERROR(VLOOKUP(A22,数据表!C:D,2,0),""),10) -> 鹏元认证日志表 | C22: authen_log | D22: =LEFT(IFERROR(VLOOKUP(C22,数据表!C:D,2,0),""),10) -> 调用第三方认证日志记 | F22: =LEFT(IFERROR(VLOOKUP(E22,数据表!C:D,2,0),""),10) | H22: =LEFT(IFERROR(VLOOKUP(G22,数据表!C:D,2,0),""),10)
A23: user_bankcard_auth | B23: =LEFT(IFERROR(VLOOKUP(A23,数据表!C:D,2,0),""),10) -> 银行卡鉴权信息表 | C23: user_bind_card | D23: =LEFT(IFERROR(VLOOKUP(C23,数据表!C:D,2,0),""),10) -> 绑定银行卡信息 | F23: =LEFT(IFERROR(VLOOKUP(E23,数据表!C:D,2,0),""),10) | H23: =LEFT(IFERROR(VLOOKUP(G23,数据表!C:D,2,0),""),10)
A24: user_bankcard_info | B24: =LEFT(IFERROR(VLOOKUP(A24,数据表!C:D,2,0),""),10) -> 银行卡信息表，原表名 | D24: =LEFT(IFERROR(VLOOKUP(C24,数据表!C:D,2,0),""),10) | F24: =LEFT(IFERROR(VLOOKUP(E24,数据表!C:D,2,0),""),10) | H24: =LEFT(IFERROR(VLOOKUP(G24,数据表!C:D,2,0),""),10)
A25: nono_studentAuth_log | B25: =LEFT(IFERROR(VLOOKUP(A25,数据表!C:D,2,0),""),10) -> 学生学籍认证历史信息 | D25: =LEFT(IFERROR(VLOOKUP(C25,数据表!C:D,2,0),""),10) | F25: =LEFT(IFERROR(VLOOKUP(E25,数据表!C:D,2,0),""),10) | H25: =LEFT(IFERROR(VLOOKUP(G25,数据表!C:D,2,0),""),10)
A26: nono_authentication | B26: =LEFT(IFERROR(VLOOKUP(A26,数据表!C:D,2,0),""),10) -> nono认证库表 | D26: =LEFT(IFERROR(VLOOKUP(C26,数据表!C:D,2,0),""),10) | F26: =LEFT(IFERROR(VLOOKUP(E26,数据表!C:D,2,0),""),10) | H26: =LEFT(IFERROR(VLOOKUP(G26,数据表!C:D,2,0),""),10)
A27: authentication_htsb | B27: =LEFT(IFERROR(VLOOKUP(A27,数据表!C:D,2,0),""),10) -> 活体识别日志表(原表 | D27: =LEFT(IFERROR(VLOOKUP(C27,数据表!C:D,2,0),""),10) | F27: =LEFT(IFERROR(VLOOKUP(E27,数据表!C:D,2,0),""),10) | H27: =LEFT(IFERROR(VLOOKUP(G27,数据表!C:D,2,0),""),10)
A28: borrows_archive | B28: =LEFT(IFERROR(VLOOKUP(A28,数据表!C:D,2,0),""),10) -> 认证表 | D28: =LEFT(IFERROR(VLOOKUP(C28,数据表!C:D,2,0),""),10) | F28: =LEFT(IFERROR(VLOOKUP(E28,数据表!C:D,2,0),""),10) | H28: =LEFT(IFERROR(VLOOKUP(G28,数据表!C:D,2,0),""),10)
A29: mxd_score_result | B29: =LEFT(IFERROR(VLOOKUP(A29,数据表!C:D,2,0),""),10) -> 名校贷评分信息表 | D29: =LEFT(IFERROR(VLOOKUP(C29,数据表!C:D,2,0),""),10) | F29: =LEFT(IFERROR(VLOOKUP(E29,数据表!C:D,2,0),""),10) | H29: =LEFT(IFERROR(VLOOKUP(G29,数据表!C:D,2,0),""),10)
A30: sesame_credit | B30: =LEFT(IFERROR(VLOOKUP(A30,数据表!C:D,2,0),""),10) -> 芝麻信用表，存放所有 | D30: =LEFT(IFERROR(VLOOKUP(C30,数据表!C:D,2,0),""),10) | E30: ORD_USER_HONOR | F30: =LEFT(IFERROR(VLOOKUP(E30,数据表!C:D,2,0),""),10) -> 用户信用表 | H30: =LEFT(IFERROR(VLOOKUP(G30,数据表!C:D,2,0),""),10)
A31: user_htsb_info | B31: =LEFT(IFERROR(VLOOKUP(A31,数据表!C:D,2,0),""),10) -> 用户活体识别信息表 | D31: =LEFT(IFERROR(VLOOKUP(C31,数据表!C:D,2,0),""),10) | F31: =LEFT(IFERROR(VLOOKUP(E31,数据表!C:D,2,0),""),10) | H31: =LEFT(IFERROR(VLOOKUP(G31,数据表!C:D,2,0),""),10)
A32: user_credit_investigation | B32: =LEFT(IFERROR(VLOOKUP(A32,数据表!C:D,2,0),""),10) -> 用户征信相关信息 | D32: =LEFT(IFERROR(VLOOKUP(C32,数据表!C:D,2,0),""),10) | F32: =LEFT(IFERROR(VLOOKUP(E32,数据表!C:D,2,0),""),10) | H32: =LEFT(IFERROR(VLOOKUP(G32,数据表!C:D,2,0),""),10)
A33: user_credit_rating_info | B33: =LEFT(IFERROR(VLOOKUP(A33,数据表!C:D,2,0),""),10) -> 用户信用证书申请 | D33: =LEFT(IFERROR(VLOOKUP(C33,数据表!C:D,2,0),""),10) | F33: =LEFT(IFERROR(VLOOKUP(E33,数据表!C:D,2,0),""),10) | H33: =LEFT(IFERROR(VLOOKUP(G33,数据表!C:D,2,0),""),10)
A34: face_beyond_result | B34: =LEFT(IFERROR(VLOOKUP(A34,数据表!C:D,2,0),""),10) -> 脸部识别，比较结果 | D34: =LEFT(IFERROR(VLOOKUP(C34,数据表!C:D,2,0),""),10) | F34: =LEFT(IFERROR(VLOOKUP(E34,数据表!C:D,2,0),""),10) | H34: =LEFT(IFERROR(VLOOKUP(G34,数据表!C:D,2,0),""),10)
A35: credit_user_htsb_info | B35: =LEFT(IFERROR(VLOOKUP(A35,数据表!C:D,2,0),""),10) -> 用户活体识别信息产品 | D35: =LEFT(IFERROR(VLOOKUP(C35,数据表!C:D,2,0),""),10) | F35: =LEFT(IFERROR(VLOOKUP(E35,数据表!C:D,2,0),""),10) | H35: =LEFT(IFERROR(VLOOKUP(G35,数据表!C:D,2,0),""),10)
B36: =LEFT(IFERROR(VLOOKUP(A36,数据表!C:D,2,0),""),10) | D36: =LEFT(IFERROR(VLOOKUP(C36,数据表!C:D,2,0),""),10) | F36: =LEFT(IFERROR(VLOOKUP(E36,数据表!C:D,2,0),""),10) | H36: =LEFT(IFERROR(VLOOKUP(G36,数据表!C:D,2,0),""),10)
A37: 登录 | B37: =LEFT(IFERROR(VLOOKUP(A37,数据表!C:D,2,0),""),10) | D37: =LEFT(IFERROR(VLOOKUP(C37,数据表!C:D,2,0),""),10) | F37: =LEFT(IFERROR(VLOOKUP(E37,数据表!C:D,2,0),""),10) | H37: =LEFT(IFERROR(VLOOKUP(G37,数据表!C:D,2,0),""),10)
A38: user_action_log | B38: =LEFT(IFERROR(VLOOKUP(A38,数据表!C:D,2,0),""),10) -> 用户操作记录表 | D38: =LEFT(IFERROR(VLOOKUP(C38,数据表!C:D,2,0),""),10) | F38: =LEFT(IFERROR(VLOOKUP(E38,数据表!C:D,2,0),""),10) | H38: =LEFT(IFERROR(VLOOKUP(G38,数据表!C:D,2,0),""),10)
A39: user_login_info | B39: =LEFT(IFERROR(VLOOKUP(A39,数据表!C:D,2,0),""),10) -> 用户登录信息 | D39: =LEFT(IFERROR(VLOOKUP(C39,数据表!C:D,2,0),""),10) | F39: =LEFT(IFERROR(VLOOKUP(E39,数据表!C:D,2,0),""),10) | H39: =LEFT(IFERROR(VLOOKUP(G39,数据表!C:D,2,0),""),10)
B40: =LEFT(IFERROR(VLOOKUP(A40,数据表!C:D,2,0),""),10) | D40: =LEFT(IFERROR(VLOOKUP(C40,数据表!C:D,2,0),""),10) | F40: =LEFT(IFERROR(VLOOKUP(E40,数据表!C:D,2,0),""),10) | H40: =LEFT(IFERROR(VLOOKUP(G40,数据表!C:D,2,0),""),10)
...

Sheet Sheet5
H2: WHERE user_id=@user_id limit 10;
H3: limit 10;
B4: SELECT * FROM | C4: activity_vip | D4: WHERE user_id=@user_id limit 10;
B5: SELECT * FROM | C5: activity_vip_label | D5: WHERE user_id=@user_id limit 10;
B6: SELECT * FROM | C6: activity_vip_physicalgoods | D6: WHERE user_id=@user_id limit 10;
B7: SELECT * FROM | C7: activity_vip_physicalgoods_info | D7: WHERE user_id=@user_id limit 10;
B8: SELECT * FROM | C8: activity_vip_praise_log | D8: WHERE user_id=@user_id limit 10;
B9: SELECT * FROM | C9: activity_vip_virtualgoods | D9: WHERE user_id=@user_id limit 10;
B10: SELECT * FROM | C10: activity_point_log | D10: WHERE user_id=@user_id limit 10;
B11: SELECT * FROM | C11: activity_prize_gain_list | D11: WHERE user_id=@user_id limit 10;
B12: SELECT * FROM | C12: activity_prize_list | D12: WHERE user_id=@user_id limit 10;

Sheet 资金账户
A1: 订单 | B1: 产品账户 | C1: 资金账户 | D1: 资金账户区别
A2: borrows_bidding | B2: user_info | C2: finance_account | D2: 7
A3: debt_buy_log | B3: user_info | C3: finance_account | D3: 7
A4: vip_form | B4: vip_account | C4: finance_account | D4: 13
A5: fund_form | B5: fund_account | C5: finance_account | D5: 27/35
A6: trans_detail | B6: user_info | C6: finance_account | D6: 42
A7: user_product | B7: merchant_regular_account | C7: finance_account | D7: 43

Sheet 计划类产品
A1: 精选计划
A6: 贴心计划
