Workbook

Sheet 中心总
A1: 2019年员工绩效评估结果汇总表 （中心总）
A2: 中心绩效等级： | B2: B
A3: 评估结果校验：
A4: 绩效等级 | B4: S | C4: A | D4: B | E4: C | F4: D
A5: 绩效分布 | B5: =VLOOKUP(B2,等级分布!A:F,2,0) -> 0.1 | C5: =VLOOKUP(B2,等级分布!A:F,3,0) -> 0.2 | D5: =VLOOKUP(B2,等级分布!A:F,4,0) -> 0.3 | E5: =VLOOKUP(B2,等级分布!A:F,5,0) -> 0.2 | F5: =VLOOKUP(B2,等级分布!A:F,6,0) -> 0.2
A6: 评估结果等级分布
A7: 是否符合规则 | B7: =IF(B6<=B5,"是","否") -> 是 | C7: =IF(C6<=C5,"是","否") -> 是 | D7: =IF(D6<=D5,"是","否") -> 是 | E7: =IF(E6<=E5,"是","否") -> 是 | F7: =IF(F6<=F5,"是","否") -> 是
A8: 注：绩效等级比例浮动规则具体见《2019年一季度绩效检视通知》
A9: 员工编码 | B9: 员工姓名 | C9: 所属中心名称 | D9: 二级部门 | E9: 岗位名称 | F9: 职级 | G9: 入职时间 | H9: 直接上级姓名 | I9: 绩效评估得分 （100分制） | J9: 排名组名称 （如xx部门/xx团队） | K9: 绩效排名 （正序，各排名组单独排名） | L9: 绩效等级 （S、A、B、C、D） | M9: 备注 | N9: 序号
A10: M01852 | B10: 于文浩 | C10: 人力资源中心 | E10: 首席人力官 | F10: P7 | G10: 43259 | H10: 黄大容
A11: M01791 | B11: 彭琛 | C11: 金融科技板块 | E11: 大智金科CEO | G11: 43198 | H11: 彭琛
A12: M02072 | B12: 锁麟 | C12: 资金板块 | E12: 资金中心总经理 | F12: M8 | G12: 43388 | H12: 黄大容
A13: M02146 | B13: 王永杰 | C13: 资金板块 | E13: COO | G13: 43452 | H13: 锁麟
A14: M00026 | B14: 肖斌 | C14: 资产板块 | E14: 大智金科执行副总裁 | G14: 43040 | H14: 黄大容
A15: M01569 | B15: 韩佳贇 | C15: 内控法务中心 | D15: 内控合规部 | E15: 内控合规总监 | F15: M5 | G15: 42950 | H15: 黄大容
A16: M00749 | B16: 周志军 | C16: 内控法务中心 | D16: 法律服务部 | E16: 法律服务部负责人 | F16: M7 | G16: 42625 | H16: 黄大容

Sheet 二级部门长
A1: 2019年员工绩效评估结果汇总表 （中心总）
A2: 中心绩效等级： | B2: B
A3: 评估结果校验：
A4: 绩效等级 | B4: S | C4: A | D4: B | E4: C | F4: D
A5: 绩效分布 | B5: =VLOOKUP(B2,等级分布!A:F,2,0) -> 0.1 | C5: =VLOOKUP(B2,等级分布!A:F,3,0) -> 0.2 | D5: =VLOOKUP(B2,等级分布!A:F,4,0) -> 0.3 | E5: =VLOOKUP(B2,等级分布!A:F,5,0) -> 0.2 | F5: =VLOOKUP(B2,等级分布!A:F,6,0) -> 0.2
A6: 评估结果等级分布
A7: 是否符合规则 | B7: =IF(B6<=B5,"是","否") -> 是 | C7: =IF(C6<=C5,"是","否") -> 是 | D7: =IF(D6<=D5,"是","否") -> 是 | E7: =IF(E6<=E5,"是","否") -> 是 | F7: =IF(F6<=F5,"是","否") -> 是
A8: 注：绩效等级比例浮动规则具体见《2019年一季度绩效检视通知》
A9: 员工编码 | B9: 员工姓名 | C9: 所属中心名称 | D9: 二级部门 | E9: 岗位名称 | F9: 职级 | G9: 入职时间 | H9: 直接上级姓名 | I9: 绩效评估得分 （100分制） | J9: 排名组名称 （如xx部门/xx团队） | K9: 绩效排名 （正序，各排名组单独排名） | L9: 绩效等级 （S、A、B、C、D） | M9: 备注 | N9: 序号
A10: M00036 | B10: 翁志军 | C10: 资产板块 | D10: 现金分期事业部 | E10: 消费金融资产部负责人 | F10: M6 | G10: 41708 | H10: 肖斌
A11: M02163 | B11: 卓敬之 | C11: 资产板块 | D11: 医美医疗板块 | E11: 医美事业部副总经理 | F11: M7 | G11: 43514 | H11: 肖斌
A12: M02167 | B12: 胡斌 | C12: 资产板块 | D12: 医美医疗板块 | E12: 业务助理总裁 | F12: M7 | G12: 43521 | H12: 肖斌
A13: M00025 | B13: 温毅娟 | C13: 资产板块 | E13: 新大房东负责人 | F13: P6 | G13: 41518 | H13: 肖斌
A14: M01685 | B14: 王语丰 | C14: 资产板块 | D14: 客户服务部 | E14: 客户服务部负责人 | F14: M7 | G14: 43024 | H14: 肖斌
A15: M00004 | B15: 王磊 | C15: 资产板块 | D15: 资产产品部 | E15: 资产产品总监 | F15: M6 | G15: 40299 | H15: 肖斌
A16: M02018 | B16: 宋效林 | C16: 资产板块 | D16: 医美医疗风控部 | E16: 风控经理 | F16: M6 | G16: 43320 | H16: 肖斌
A17: M01351 | B17: 陈坚栋 | C17: 资产板块 | D17: 信审部 | E17: 信审部负责人 | F17: M5 | G17: 42842 | H17: 肖斌
A18: M00683 | B18: 王燕 | C18: 资产板块 | D18: 信贷风控部 | E18: 信贷风控部负责人 | F18: M6 | G18: 42604 | H18: 肖斌
A19: M00417 | B19: 张勇耀 | C19: 资产板块 | D19: 贷后管理部 | E19: 贷后管理部负责人 | F19: M6 | G19: 42493 | H19: 肖斌
A20: M00615 | B20: 叶宁 | C20: 资产板块 | D20: BI数据分析平台部 | E20: BI数据分析平台部负责人 | F20: P5 | G20: 42576 | H20: 肖斌
A21: M01775 | B21: 王洪雨 | C21: 资金板块 | D21: 用户服务部 | E21: 用户服务部总监 | F21: P6 | G21: 43192 | H21: 锁麟
A22: M01736 | B22: 卢元强 | C22: 资金板块 | D22: 市场品牌部 | E22: 媒体公关总监 | F22: M6 | G22: 43108 | H22: 锁麟
A23: M00175 | B23: 张杨 | C23: 资金板块 | D23: 财神运营部 | E23: 财神爷爷运营总监 | F23: P5 | G23: 42264 | H23: 锁麟
A24: M02121 | B24: 李伟 | C24: 资金板块 | D24: 财富运营部 | E24: 财富运营部负责人 | F24: M6 | G24: 43430 | H24: 锁麟
A25: M00095 | B25: 仇雷 | C25: 资金板块 | D25: 上海技术部 | E25: 资金应用开发部负责人 | F25: M5 | G25: 42060 | H25: 刘佩华
A26: M00332 | B26: 肖少华 | C26: 资金板块 | D26: 北京技术部 | E26: 北京移动组负责人 | F26: P5 | G26: 42443 | H26: 刘佩华
A27: M02017 | B27: 庄浩英 | C27: 金融科技板块 | E27: 首席技术官 | F27: P7 | G27: 43320 | H27: 彭琛
A28: M02071 | B28: 李胜书 | C28: 金融科技板块 | D28: 移动开发部 | E28: 上海移动组负责人 | F28: P5 | G28: 43383 | H28: 庄浩英
A29: M01394 | B29: 陈霞 | C29: 金融科技板块 | D29: 质量控制部 | E29: 质量控制部负责人 | F29: M5 | G29: 42851 | H29: 庄浩英
A30: M00430 | B30: 于骁丹 | C30: 金融科技板块 | D30: 基础平台开发部 | E30: 基础平台开发部负责人 | F30: M5 | G30: 42499 | H30: 庄浩英
A31: M02038 | B31: 陆士超 | C31: 金融科技板块 | D31: 基础运维部 | E31: 基础运维部负责人 | F31: M5 | G31: 43361 | H31: 庄浩英
A32: M00048 | B32: 陈丽丽 | C32: 财务中心 | D32: 资金交易部 | E32: 资金交易部负责人 | F32: M5 | G32: 41779 | H32: 周玉琳
A33: M01588 | B33: 张猛 | C33: 财务中心 | D33: 资金交易部 | E33: 流动性管理岗 | F33: P3 | G33: 42963 | H33: 陈丽丽
A34: M00016 | B34: 王幽雅 | C34: 财务中心 | D34: 会计部 | E34: 会计部副职 | F34: M5 | G34: 41295 | H34: 谢知君
A35: M00291 | B35: 金婷 | C35: 财务中心 | D35: 会计部 | E35: 会计部负责人 | F35: M6 | G35: 42387 | H35: 谢知君
A36: M01750 | B36: 杨玉 | C36: 人力资源中心 | D36: 组织规划与配置部 | E36: 组织规划与配置部负责人 | F36: M5 | G36: 43136 | H36: 于文浩
A37: M01834 | B37: 刘艳 | C37: 人力资源中心 | D37: 行政管理部 | E37: 行政管理部负责人 | F37: M6 | G37: 43234 | H37: 于文浩

Sheet 总裁办
A1: 2019年员工绩效评估结果汇总表 （中心总）
A2: 中心绩效等级： | B2: B
A3: 评估结果校验：
A4: 绩效等级 | B4: S | C4: A | D4: B | E4: C | F4: D
A5: 绩效分布 | B5: =VLOOKUP(B2,等级分布!A:F,2,0) -> 0.1 | C5: =VLOOKUP(B2,等级分布!A:F,3,0) -> 0.2 | D5: =VLOOKUP(B2,等级分布!A:F,4,0) -> 0.3 | E5: =VLOOKUP(B2,等级分布!A:F,5,0) -> 0.2 | F5: =VLOOKUP(B2,等级分布!A:F,6,0) -> 0.2
A6: 评估结果等级分布
A7: 是否符合规则 | B7: =IF(B6<=B5,"是","否") -> 是 | C7: =IF(C6<=C5,"是","否") -> 是 | D7: =IF(D6<=D5,"是","否") -> 是 | E7: =IF(E6<=E5,"是","否") -> 是 | F7: =IF(F6<=F5,"是","否") -> 是
A8: 注：绩效等级比例浮动规则具体见《2019年一季度绩效检视通知》
A9: 员工编码 | B9: 员工姓名 | C9: 所属中心名称 | D9: 二级部门 | E9: 岗位名称 | F9: 职级 | G9: 入职时间 | H9: 直接上级姓名 | I9: 绩效评估得分 （100分制） | J9: 排名组名称 （如xx部门/xx团队） | K9: 绩效排名 （正序，各排名组单独排名） | L9: 绩效等级 （S、A、B、C、D） | M9: 备注 | N9: 序号
A10: M00001 | B10: 黄大容 | C10: 总裁办 | E10: 集团CEO | F10: M10 | G10: 39979 | H10: 黄大容
A11: M00007 | B11: 龚文魁 | C11: 总裁办 | E11: 董事长助理 | F11: P7 | G11: 40653 | H11: 黄大容
A12: M00418 | B12: 翁明军 | C12: 总裁办 | E12: 董事长高级助理 | F12: M9 | G12: 42493 | H12: 黄大容
A13: M01476 | B13: 吕文豪 | C13: 总裁办 | E13: 司机 | F13: P1 | G13: 42898 | H13: 黄大容
A14: M01571 | B14: 陈弘 | C14: 总裁办 | E14: 顾问 | F14: M9 | G14: 42954 | H14: 黄大容
A15: M01656 | B15: 周玉琳 | C15: 总裁办 | E15: 首席策略官兼董事长助理 | F15: P7 | G15: 43003 | H15: 黄大容
A16: M01684 | B16: 石勇 | C16: 总裁办 | E16: 顾问 | G16: 42991 | H16: 黄大容
B17: 徐颖 | C17: 总裁办 | H17: 黄大容
B18: JohnDonovan | C18: 总裁办 | H18: 黄大容
B19: WilfredDaye | C19: 总裁办 | H19: 黄大容
A20: M00383 | B20: 李尚坤 | C20: 总裁办 | E20: 市场拓展岗 | F20: P4 | G20: 42476 | H20: 宋墨
A21: M01462 | B21: 刘瑜 | C21: 总裁办 | E21: 市场拓展岗 | F21: P1 | G21: 43059 | H21: 宋墨
A22: M01730 | B22: 宋墨 | C22: 总裁办 | E22: 国际事业团队负责人 | F22: M6 | G22: 43070 | H22: 黄大容
A23: M01751 | B23: 顾钋 | C23: 总裁办 | E23: 市场拓展岗 | F23: P4 | G23: 43122 | H23: 宋墨
A24: M01445 | B24: 王煜 | C24: 总裁办 | E24: 顾问 | F24: M6 | G24: 42878 | H24: 黄大容
A25: M02159 | B25: 杨笑一 | C25: 总裁办 | E25: 顾问 | G25: 43468 | H25: 黄大容
A26: M00762 | B26: 徐韬 | C26: 总裁办 | E26: 首席监察官 | F26: M6 | G26: 42627 | H26: 黄大容
A27: M00015 | B27: 曾庆辉 | C27: 总裁办 | E27: 顾问 | F27: M8 | G27: 41267 | H27: 黄大容
A28: M00540 | B28: LIXIAOZHONG | C28: 总裁办 | E28: 副总裁 | F28: M9 | G28: 42552 | H28: 黄大容
A29: M00673 | B29: 何渊 | C29: 总裁办 | E29: 顾问 | F29: P6 | G29: 42597 | H29: 黄大容
A30: M01104 | B30: 石蔚明 | C30: 总裁办 | E30: 副总裁 | F30: M8 | G30: 42758 | H30: 黄大容
A31: M01739 | B31: 蒲爱琼 | C31: 总裁办 | E31: 区域总经理 | F31: P7 | G31: 43160 | H31: 黄大容

Sheet 资产板块
A1: 2019年员工绩效评估结果汇总表 （资产板块）
A2: 中心绩效等级： | B2: B
A3: 评估结果校验：
A4: 绩效等级 | B4: S | C4: A | D4: B | E4: C | F4: D
A5: 绩效分布 | B5: =VLOOKUP(B2,等级分布!A:F,2,0) -> 0.1 | C5: =VLOOKUP(B2,等级分布!A:F,3,0) -> 0.2 | D5: =VLOOKUP(B2,等级分布!A:F,4,0) -> 0.3 | E5: =VLOOKUP(B2,等级分布!A:F,5,0) -> 0.2 | F5: =VLOOKUP(B2,等级分布!A:F,6,0) -> 0.2
A6: 评估结果等级分布
A7: 是否符合规则 | B7: =IF(B6<=B5,"是","否") -> 是 | C7: =IF(C6<=C5,"是","否") -> 是 | D7: =IF(D6<=D5,"是","否") -> 是 | E7: =IF(E6<=E5,"是","否") -> 是 | F7: =IF(F6<=F5,"是","否") -> 是
A8: 注：绩效等级比例浮动规则具体见《2019年一季度绩效检视通知》
A9: 员工编码 | B9: 员工姓名 | C9: 所属中心名称 | D9: 二级部门 | E9: 岗位名称 | F9: 职级 | G9: 入职时间 | H9: 直接上级姓名 | I9: 绩效评估得分 （100分制） | J9: 排名组名称 （如xx部门/xx团队） | K9: 绩效排名 （正序，各排名组单独排名） | L9: 绩效等级 （S、A、B、C、D） | M9: 备注 | N9: 序号
A10: M02125 | B10: 周理瑶 | C10: 资产板块 | E10: 市场品牌岗 | F10: P3 | G10: 43318 | H10: 肖斌
A11: M01970 | B11: 冯岩 | C11: 资产板块 | E11: 业务副总裁助理 | F11: P3 | G11: 43292 | H11: 肖斌
A12: M00004 | B12: 王磊 | C12: 资产板块 | D12: 资产产品部 | E12: 资产产品总监 | F12: M6 | G12: 40299 | H12: 肖斌
A13: M01307 | B13: 杨高 | C13: 资产板块 | D13: 资产产品部 | E13: 资产产品经理 | F13: P4 | G13: 42826 | H13: 王磊
A14: M01630 | B14: 王芬 | C14: 资产板块 | D14: 资产产品部 | E14: 助理产品经理 | F14: B1 | G14: 42989 | H14: 王磊
A15: M01830 | B15: 马晓玥 | C15: 资产板块 | D15: 资产产品部 | E15: 资产产品经理 | F15: P4 | G15: 43229 | H15: 王磊
A16: M01832 | B16: 何延锦 | C16: 资产板块 | D16: 资产产品部 | E16: 产品岗 | F16: P4 | G16: 43234 | H16: 王磊
A17: M02160 | B17: 宋伟冬 | C17: 资产板块 | D17: 资产产品部 | E17: 金融产品岗 | F17: P2 | G17: 43497 | H17: 王磊
A18: M02163 | B18: 卓敬之 | C18: 资产板块 | D18: 医美医疗板块 | E18: 医美事业部副总经理 | F18: M7 | G18: 43514 | H18: 肖斌
A19: M02167 | B19: 胡斌 | C19: 资产板块 | D19: 医美医疗板块 | E19: 业务助理总裁 | F19: M7 | G19: 43521 | H19: 肖斌
A20: M00313 | B20: 李文娟 | C20: 资产板块 | D20: 医美医疗板块 | E20: 渠道合作部副总经理岗 | F20: M5 | G20: 42430 | H20: 胡斌
A21: M00618 | B21: 窦欣桐 | C21: 资产板块 | D21: 医美医疗板块 | E21: 运营岗 | F21: P3 | G21: 42576 | H21: 李文娟
A22: M00769 | B22: 梁晓 | C22: 资产板块 | D22: 医美医疗板块 | E22: 运营岗 | F22: P2 | G22: 42631 | H22: 李文娟
A23: M00911 | B23: 朱建斌 | C23: 资产板块 | D23: 医美医疗板块 | E23: 商务拓展岗 | F23: B1 | G23: 42686 | H23: 李文娟
... A97: M02105 | B97: 彭佳春 | C97: 资产板块 | D97: 客户服务部 | E97: 上海客服岗 | F97: B1 | G97: 43388 | H97: 张倩
A98: M01930 | B98: 王欣怡 | C98: 资产板块 | D98: 客户服务部 | E98: 客服专员 | G98: 43270 | H98: 张倩
A99: M02135 | B99: 李昶键 | C99: 资产板块 | D99: 客户服务部 | E99: 电话销售 | G99: 43439 | H99: 陶君敏
A100: M02136 | B100: 康永敏 | C100: 资产板块 | D100: 客户服务部 | E100: 电话销售 | G100: 43439 | H100: 陶君敏
A101: M02137 | B101: 彭茜敏 | C101: 资产板块 | D101: 客户服务部 | E101: 电话销售 | G101: 43439 | H101: 陶君敏
A102: M02138 | B102: 严双双 | C102: 资产板块 | D102: 客户服务部 | E102: 电话销售 | G102: 43439 | H102: 陶君敏
A103: M02139 | B103: 伍小玲 | C103: 资产板块 | D103: 客户服务部 | E103: 电话销售 | G103: 43439 | H103: 陶君敏
A104: M00211 | B104: 毛晨 | C104: 资产板块 | D104: 客户服务部 | E104: 客诉组负责人（代理） | F104: B2 | G104: 42310 | H104: 陶君敏
A105: M01482 | B105: 郑坤 | C105: 资产板块 | D105: 客户服务部 | E105: 上海客诉岗 | F105: B1 | G105: 42901 | H105: 毛晨
A106: M02142 | B106: 李财 | C106: 资产板块 | D106: 客户服务部 | E106: 电话销售 | G106: 43452 | H106: 陶君敏
A107: M02143 | B107: 熊祥霞 | C107: 资产板块 | D107: 客户服务部 | E107: 电话销售 | G107: 43452 | H107: 陶君敏
A108: M02144 | B108: 王芳 | C108: 资产板块 | D108: 客户服务部 | E108: 电话销售 | G108: 43452 | H108: 陶君敏
A109: M02152 | B109: 毛柳 | C109: 资产板块 | D109: 客户服务部 | E109: 电话销售 | G109: 43460 | H109: 陶君敏
A110: M02153 | B110: 雷含雨 | C110: 资产板块 | D110: 客户服务部 | E110: 电话销售 | G110: 43460 | H110: 陶君敏
A111: M01788 | B111: 熊保华 | C111: 资产板块 | D111: 代运营事业部 | E111: 业务BD | F111: P5 | G111: 43199 | H111: 肖斌
A112: M00025 | B112: 温毅娟 | C112: 资产板块 | E112: 新大房东负责人 | F112: P6 | G112: 41518 | H112: 肖斌
A113: M00485 | B113: 王娟 | C113: 资产板块 | E113: 贷后外访岗 | F113: P1 | G113: 42527 | H113: 温毅娟
...

Sheet 资金板块
A1: 2019年员工绩效评估结果汇总表 （资金板块）
A2: 中心绩效等级： | B2: B
A3: 评估结果校验：
A4: 绩效等级 | B4: S | C4: A | D4: B | E4: C | F4: D
A5: 绩效分布 | B5: =VLOOKUP(B2,等级分布!A:F,2,0) -> 0.1 | C5: =VLOOKUP(B2,等级分布!A:F,3,0) -> 0.2 | D5: =VLOOKUP(B2,等级分布!A:F,4,0) -> 0.3 | E5: =VLOOKUP(B2,等级分布!A:F,5,0) -> 0.2 | F5: =VLOOKUP(B2,等级分布!A:F,6,0) -> 0.2
A6: 评估结果等级分布
A7: 是否符合规则 | B7: =IF(B6<=B5,"是","否") -> 是 | C7: =IF(C6<=C5,"是","否") -> 是 | D7: =IF(D6<=D5,"是","否") -> 是 | E7: =IF(E6<=E5,"是","否") -> 是 | F7: =IF(F6<=F5,"是","否") -> 是
A8: 注：绩效等级比例浮动规则具体见《2019年一季度绩效检视通知》
A9: 员工编码 | B9: 员工姓名 | C9: 所属中心名称 | D9: 二级部门 | E9: 岗位名称 | F9: 职级 | G9: 入职时间 | H9: 直接上级姓名 | I9: 绩效评估得分 （100分制） | J9: 排名组名称 （如xx部门/xx团队） | K9: 绩效排名 （正序，各排名组单独排名） | L9: 绩效等级 （S、A、B、C、D） | M9: 备注 | N9: 序号
A10: M00041 | B10: 刘佩华 | C10: 资金板块 | E10: CTO助理 | F10: M6 | G10: 41730 | H10: 锁麟
A11: M01945 | B11: 王阐艺 | C11: 资金板块 | E11: 项目助理岗 | F11: P2 | G11: 43283 | H11: 刘佩华
A12: M00523 | B12: 李永强 | C12: 资金板块 | E12: PMO岗 | F12: P5 | G12: 42541 | H12: 锁麟
A13: M01775 | B13: 王洪雨 | C13: 资金板块 | D13: 用户服务部 | E13: 用户服务部总监 | F13: P6 | G13: 43192 | H13: 锁麟
A14: M01806 | B14: 赵朋 | C14: 资金板块 | D14: 用户服务部 | E14: 资金客服组负责人 | F14: B4 | G14: 43213 | H14: 王洪雨
A15: M01823 | B15: 卓艳 | C15: 资金板块 | D15: 用户服务部 | E15: 客服岗 | F15: B1 | G15: 43227 | H15: 赵朋
A16: M01862 | B16: 黎欣璋 | C16: 资金板块 | D16: 用户服务部 | E16: 客服岗 | F16: B1 | G16: 43248 | H16: 赵朋
A17: M01863 | B17: 姚倩 | C17: 资金板块 | D17: 用户服务部 | E17: 客服岗 | F17: B1 | G17: 43248 | H17: 赵朋
A18: M01932 | B18: 张玉婷 | C18: 资金板块 | D18: 用户服务部 | E18: 客服岗 | F18: B1 | G18: 43276 | H18: 赵朋
A19: M01964 | B19: 季一青 | C19: 资金板块 | D19: 用户服务部 | E19: 客服岗 | F19: B1 | G19: 43290 | H19: 赵朋
A20: M02030 | B20: 张彩娟 | C20: 资金板块 | D20: 用户服务部 | E20: 客服岗 | F20: B1 | G20: 43334 | H20: 赵朋
A21: M00843 | B21: 张保磊 | C21: 资金板块 | D21: 用户服务部 | E21: 用户服务主管 | F21: B1 | G21: 42667 | H21: 王洪雨
A22: M01161 | B22: 钱广凯 | C22: 资金板块 | D22: 用户服务部 | E22: 用户服务专员 | F22: B1 | G22: 42788 | H22: 张保磊
A23: M01415 | B23: 严仍伟 | C23: 资金板块 | D23: 用户服务部 | E23: 用户服务专员 | F23: B1 | G23: 42863 | H23: 张保磊
A24: M01544 | B24: 高瑞 | C24: 资金板块 | D24: 用户服务部 | E24: 用户服务专员 | F24: B1 | G24: 42919 | H24: 张保磊
... A115: M01959 | B115: 蔡莹 | C115: 资金板块 | D115: 北京技术部 | E115: 测试开发岗 | F115: P3 | G115: 43286 | H115: 顼士超
A116: M00284 | B116: 李晶晶 | C116: 资金板块 | E116: 项目岗 | F116: P4 | G116: 42374 | H116: 郑雷
A117: M00776 | B117: 陈铭佳 | C117: 资金板块 | E117: 项目岗 | F117: P3 | G117: 42632 | H117: 郑雷
A118: M00079 | B118: 徐熠 | C118: 资金板块 | D118: 财富运营部 | E118: 用户运营组负责人 | F118: P5 | G118: 41944 | H118: 李伟
A119: M00797 | B119: 高丽莎 | C119: 资金板块 | D119: 上海技术部 | E119: 大前端服务研发岗 | F119: P3 | G119: 42640 | H119: 刘重远
A120: M01014 | B120: 周奇 | C120: 资金板块 | D120: 财神运营部 | E120: 视觉设计岗 | F120: P3 | G120: 42716 | H120: 张杨
A121: M01855 | B121: 高萌 | C121: 资金板块 | D121: 财神运营部 | E121: 用户运营岗 | F121: P3 | G121: 43241 | H121: 张杨
A122: M01857 | B122: 王行 | C122: 资金板块 | D122: 财富运营部 | E122: 渠道运营岗 | F122: P3 | G122: 43243 | H122: 徐帅
A123: M02039 | B123: 朱红晨 | C123: 资金板块 | D123: 用户服务部 | E123: 客服岗 | F123: B1 | G123: 43362 | H123: 赵朋
A124: M02106 | B124: 陈婷 | C124: 资金板块 | D124: 用户服务部 | E124: 投资顾问 | F124: B2 | G124: 43404 | H124: 张保磊
A125: M02140 | B125: 李昀臻 | C125: 资金板块 | D125: 用户服务部 | E125: 投资顾问 | F125: B1 | G125: 43447 | H125: 张保磊
A126: M02177 | B126: 黄琴倩 | C126: 资金板块 | D126: 用户服务部 | E126: 400客服 | F126: B1 | G126: 43530 | H126: 赵朋
A127: M02180 | B127: 费富亮 | C127: 资金板块 | D127: 用户服务部 | E127: 投资顾问 | F127: B1-2 | G127: 43536 | H127: 赵朋
A128: M02182 | B128: 黄秀红 | C128: 资金板块 | D128: 用户服务部 | E128: 投资顾问 | F128: B1-2 | G128: 43536 | H128: 赵朋
A129: M02185 | B129: 吕红 | C129: 资金板块 | D129: 用户服务部 | E129: 400客服 | F129: B1 | G129: 43544 | H129: 赵朋
A130: M02188 | B130: 孟祥一 | C130: 资金板块 | D130: 用户服务部 | E130: 投资顾问 | F130: B1-2 | G130: 43546 | H130: 张保磊

Sheet 金融科技
A1: 2019年员工绩效评估结果汇总表 （金融科技）
A2: 中心绩效等级： | B2: B
A3: 评估结果校验：
A4: 绩效等级 | B4: S | C4: A | D4: B | E4: C | F4: D
A5: 绩效分布 | B5: =VLOOKUP(B2,等级分布!A:F,2,0) -> 0.1 | C5: =VLOOKUP(B2,等级分布!A:F,3,0) -> 0.2 | D5: =VLOOKUP(B2,等级分布!A:F,4,0) -> 0.3 | E5: =VLOOKUP(B2,等级分布!A:F,5,0) -> 0.2 | F5: =VLOOKUP(B2,等级分布!A:F,6,0) -> 0.2
A6: 评估结果等级分布
A7: 是否符合规则 | B7: =IF(B6<=B5,"是","否") -> 是 | C7: =IF(C6<=C5,"是","否") -> 是 | D7: =IF(D6<=D5,"是","否") -> 是 | E7: =IF(E6<=E5,"是","否") -> 是 | F7: =IF(F6<=F5,"是","否") -> 是
A8: 注：绩效等级比例浮动规则具体见《2019年一季度绩效检视通知》
A9: 员工编码 | B9: 员工姓名 | C9: 所属中心名称 | D9: 二级部门 | E9: 岗位名称 | F9: 职级 | G9: 入职时间 | H9: 直接上级姓名 | I9: 绩效评估得分 （100分制） | J9: 排名组名称 （如xx部门/xx团队） | K9: 绩效排名 （正序，各排名组单独排名） | L9: 绩效等级 （S、A、B、C、D） | M9: 备注 | N9: 序号
A10: M00046 | B10: 陈利华 | C10: 金融科技板块 | D10: 机构资金拓展部 | E10: 资金中心总经理助理 | F10: M8 | G10: 41778 | H10: 彭琛
A11: M00968 | B11: 方煜东 | C11: 金融科技板块 | D11: 资产应用开发部 | E11: JAVA开发岗 | F11: P5 | G11: 42702 | H11: 庄浩英
A12: M02126 | B12: 代小虎 | C12: 金融科技板块 | D12: 资产应用开发部 | E12: JAVA开发岗 | F12: P2 | G12: 43160 | H12: 庄浩英
A13: M02129 | B13: 莫瑞海 | C13: 金融科技板块 | D13: 资产应用开发部 | E13: 资深JAVA开发岗 | F13: P2 | G13: 43213 | H13: 庄浩英
A14: M00300 | B14: 叶思敏 | C14: 金融科技板块 | D14: 资产应用开发部 | E14: JAVA开发岗 | F14: P3 | G14: 42401 | H14: 庄浩英
A15: M00403 | B15: 商杨子 | C15: 金融科技板块 | D15: 资产应用开发部 | E15: JAVA开发岗 | F15: P1 | G15: 42485 | H15: 庄浩英
A16: M00503 | B16: 吴文蓝 | C16: 金融科技板块 | D16: 资产应用开发部 | E16: 平台研发组负责人 | F16: P4 | G16: 42529 | H16: 庄浩英
A17: M01013 | B17: 俞俊烨 | C17: 金融科技板块 | D17: 资产应用开发部 | E17: JAVA开发岗 | F17: P3 | G17: 42716 | H17: 庄浩英
A18: M02115 | B18: 肖尧 | C18: 金融科技板块 | D18: 资产应用开发部 | E18: JAVA开发岗 | F18: P3 | G18: 43420 | H18: 庄浩英
A19: M00401 | B19: 吴礼通 | C19: 金融科技板块 | D19: 资产应用开发部 | E19: JAVA开发岗 | F19: P1 | G19: 42485 | H19: 庄浩英
A20: M00927 | B20: 丁升 | C20: 金融科技板块 | D20: 资产应用开发部 | E20: JAVA开发岗 | F20: P4 | G20: 42688 | H20: 庄浩英
A21: M01962 | B21: 谈浩 | C21: 金融科技板块 | D21: 资产应用开发部 | E21: JAVA开发岗 | F21: P4 | G21: 43290 | H21: 庄浩英
... A103: M00240 | B103: 凡凯 | C103: 金融科技板块 | D103: 机构资产拓展部 | E103: 创新资产事业部总监岗 | F103: M5 | G103: 42327 | H103: 彭琛
A104: M02017 | B104: 庄浩英 | C104: 金融科技板块 | E104: 首席技术官 | F104: P7 | G104: 43320 | H104: 彭琛
A105: M00076 | B105: 王国栋 | C105: 金融科技板块 | D105: 移动开发部 | E105: IOS研发组负责人 | F105: P5 | G105: 41922 | H105: 李胜书
A106: M00097 | B106: 刘俏 | C106: 金融科技板块 | D106: 资产应用开发部 | E106: 资产应用开发负责人 | F106: P5 | G106: 42066 | H106: 庄浩英
A107: M00208 | B107: 王健军 | C107: 金融科技板块 | D107: 资产应用开发部 | E107: JAVA开发岗 | F107: P3 | G107: 42309 | H107: 庄浩英
A108: M00262 | B108: 谷旋 | C108: 金融科技板块 | E108: 开发高级经理岗 | F108: P4 | G108: 42348 | H108: 庄浩英
A109: M00285 | B109: 李瑞友 | C109: 金融科技板块 | D109: 基础运维部 | E109: DBA小组负责人 | F109: P5 | G109: 42375 | H109: 陆士超
A110: M00412 | B110: 张奎 | C110: 金融科技板块 | D110: 资产应用开发部 | E110: 风险研发负责人 | F110: P5 | G110: 42487 | H110: 庄浩英
A111: M00461 | B111: 黄伟 | C111: 金融科技板块 | E111: 测试高级经理岗 | F111: P4 | G111: 42515 | H111: 庄浩英
A112: M00638 | B112: 卢永党 | C112: 金融科技板块 | D112: 资产应用开发部 | E112: JAVA开发岗 | F112: P4 | G112: 42583 | H112: 庄浩英
A113: M00689 | B113: 孙志强 | C113: 金融科技板块 | D113: 资产应用开发部 | E113: 测试开发岗 | F113: P2 | G113: 42604 | H113: 庄浩英
A114: M00757 | B114: 肖林 | C114: 金融科技板块 | D114: 资产应用开发部 | E114: JAVA开发岗 | F114: P4 | G114: 42625 | H114: 庄浩英
A115: M00780 | B115: 陆岳 | C115: 金融科技板块 | D115: 质量控制部 | E115: 资产测试组负责人 | F115: P5 | G115: 42632 | H115: 陈霞
A116: M01001 | B116: 卢丛丛 | C116: 金融科技板块 | D116: 移动开发部 | E116: 移动前端开发岗 | F116: P3 | G116: 42712 | H116: 刘重远
A117: M01612 | B117: 韩琳 | C117: 金融科技板块 | D117: 资产应用开发部 | E117: JAVA开发岗 | F117: P3 | G117: 42979 | H117: 庄浩英
A118: M01639 | B118: 鲁成刚 | C118: 金融科技板块 | D118: 基础运维部 | E118: 应用运维组负责人 | F118: P5 | G118: 42996 | H118: 陆士超
A119: M01727 | B119: 王安天 | C119: 金融科技板块 | D119: 基础平台开发部 | E119: IT信息岗 | F119: B3 | G119: 43089 | H119: 顾成利
A120: M02124 | B120: 吴子传 | C120: 金融科技板块 | D120: 机构资金拓展部 | E120: 高级技术专家 | F120: P4 | G120: 43262 | H120: 彭琛
A121: M02151 | B121: 丁龙飞 | C121: 金融科技板块 | D121: 机构资金拓展部 | E121: 技术项目总监 | F121: P5 | G121: 43451 | H121: 彭琛

Sheet 财务中心
A1: 2019年员工绩效评估结果汇总表 （财务中心）
A2: 中心绩效等级： | B2: B
A3: 评估结果校验：
A4: 绩效等级 | B4: S | C4: A | D4: B | E4: C | F4: D
A5: 绩效分布 | B5: =VLOOKUP(B2,等级分布!A:F,2,0) -> 0.1 | C5: =VLOOKUP(B2,等级分布!A:F,3,0) -> 0.2 | D5: =VLOOKUP(B2,等级分布!A:F,4,0) -> 0.3 | E5: =VLOOKUP(B2,等级分布!A:F,5,0) -> 0.2 | F5: =VLOOKUP(B2,等级分布!A:F,6,0) -> 0.2
A6: 评估结果等级分布
A7: 是否符合规则 | B7: =IF(B6<=B5,"是","否") -> 是 | C7: =IF(C6<=C5,"是","否") -> 是 | D7: =IF(D6<=D5,"是","否") -> 是 | E7: =IF(E6<=E5,"是","否") -> 是 | F7: =IF(F6<=F5,"是","否") -> 是
A8: 注：绩效等级比例浮动规则具体见《2019年一季度绩效检视通知》
A9: 员工编码 | B9: 员工姓名 | C9: 所属中心名称 | D9: 二级部门 | E9: 岗位名称 | F9: 职级 | G9: 入职时间 | H9: 直接上级姓名 | I9: 绩效评估得分 （100分制） | J9: 排名组名称 （如xx部门/xx团队） | K9: 绩效排名 （正序，各排名组单独排名） | L9: 绩效等级 （S、A、B、C、D） | M9: 备注 | N9: 序号
A10: M00005 | B10: 申佳 | C10: 财务中心 | D10: 资金交易部 | E10: 资金核查岗 | F10: P3 | G10: 40603 | H10: 陈丽丽
A11: M00130 | B11: 唐心怡 | C11: 财务中心 | D11: 资金交易部 | E11: 资金支付岗 | F11: P2 | G11: 42198 | H11: 陈丽丽
A12: M01344 | B12: 常帅 | C12: 财务中心 | D12: 资金交易部 | E12: 资金交易岗 | F12: P1 | G12: 42837 | H12: 陈丽丽
A13: M01417 | B13: 夏群 | C13: 财务中心 | D13: 资金交易部 | E13: 资金交易岗 | F13: P2 | G13: 42863 | H13: 陈丽丽
A14: M01724 | B14: 吴裔斐 | C14: 财务中心 | D14: 资金交易部 | E14: 资金支付岗 | F14: P1 | G14: 43080 | H14: 陈丽丽
A15: M01714 | B15: 陈思伊 | C15: 财务中心 | D15: 资金交易部 | E15: 资金管理岗 | F15: P2 | G15: 43066 | H15: 张猛
A16: M02109 | B16: 王霄 | C16: 财务中心 | D16: 资金交易部 | E16: 资金会计岗 | F16: P1 | G16: 43409 | H16: 张猛
A17: M00048 | B17: 陈丽丽 | C17: 财务中心 | D17: 资金交易部 | E17: 资金交易部负责人 | F17: M5 | G17: 41779 | H17: 周玉琳
A18: M01588 | B18: 张猛 | C18: 财务中心 | D18: 资金交易部 | E18: 流动性管理岗 | F18: P3 | G18: 42963 | H18: 陈丽丽
A19: M01195 | B19: 赵韦 | C19: 财务中心 | D19: 会计部 | E19: 会计核算岗 | F19: P1 | G19: 42800 | H19: 王幽雅
A20: M02009 | B20: 章月链 | C20: 财务中心 | D20: 会计部 | E20: 会计核算岗 | F20: P3 | G20: 43313 | H20: 王幽雅
A21: M00002 | B21: 龚俊平 | C21: 财务中心 | D21: 会计部 | E21: 出纳岗 | F21: P3 | G21: 39979 | H21: 王幽雅
... A36: M00957 | B36: 郝若阳 | C36: 财务中心 | D36: 资金交易部 | E36: 资金交易岗 | F36: B1 | G36: 42697 | H36: 陈丽丽
A37: M01827 | B37: 熊娟 | C37: 财务中心 | E37: CFO秘书 | F37: P1 | G37: 43229 | H37: 谢知君
A38: M02019 | B38: 谢知君 | C38: 财务中心 | E38: 首席财务官 | G38: 43298 | H38: 黄大容

Sheet 人力资源中心
A1: 2019年员工绩效评估结果汇总表 （人力资源中心）
A2: 中心绩效等级： | B2: B
A3: 评估结果校验：
A4: 绩效等级 | B4: S | C4: A | D4: B | E4: C | F4: D
A5: 绩效分布目标 | B5: =VLOOKUP(B2,等级分布!A:F,2,0) -> 0.1 | C5: =VLOOKUP(B2,等级分布!A:F,3,0) -> 0.2 | D5: =VLOOKUP(B2,等级分布!A:F,4,0) -> 0.3 | E5: =VLOOKUP(B2,等级分布!A:F,5,0) -> 0.2 | F5: =VLOOKUP(B2,等级分布!A:F,6,0) -> 0.2
A6: 评估结果等级分布
A7: 是否符合规则 | B7: =IF(B6<=B5,"是","否") -> 是 | C7: =IF(C6<=C5,"是","否") -> 是 | D7: =IF(D6<=D5,"是","否") -> 是 | E7: =IF(E6<=E5,"是","否") -> 是 | F7: =IF(F6<=F5,"是","否") -> 是
A8: 注：绩效等级比例浮动规则具体见《2019年一季度绩效检视通知》
A9: 员工编码 | B9: 员工姓名 | C9: 所属中心名称 | D9: 二级部门 | E9: 岗位名称 | F9: 职级 | G9: 入职时间 | H9: 直接上级姓名 | I9: 绩效评估得分 （100分制） | J9: 排名组名称 （如xx部门/xx团队） | K9: 绩效排名 （正序，各排名组单独排名） | L9: 绩效等级 （S、A、B、C、D） | M9: 备注 | N9: 序号
A10: M01750 | B10: 杨玉 | C10: 人力资源中心 | D10: 组织规划与配置部 | E10: 组织规划与配置部负责人 | F10: M5 | G10: 43136 | H10: 于文浩
A11: M02134 | B11: 徐丽娟 | C11: 人力资源中心 | D11: 组织规划与配置部 | E11: 组织规划组负责人 | F11: P4 | G11: 43446 | H11: 杨玉
A12: M00973 | B12: 董佳佳 | C12: 人力资源中心 | D12: 组织规划与配置部 | E12: 组织规划岗 | F12: P2 | G12: 42704 | H12: 徐丽娟
A13: M02122 | B13: 彭海娜 | C13: 人力资源中心 | D13: 组织规划与配置部 | E13: 招聘配置组负责人 | F13: P3 | G13: 43430 | H13: 杨玉
A14: M01800 | B14: 施艳芸 | C14: 人力资源中心 | D14: 组织规划与配置部 | E14: 招聘实施岗 | F14: P1 | G14: 43209 | H14: 彭海娜
A15: M00378 | B15: 荣佳丽 | C15: 人力资源中心 | D15: 员工管理与发展部 | E15: 员工关系岗 | F15: P4 | G15: 42473 | H15: 胡荣萍
A16: M02089 | B16: 苏燕晖 | C16: 人力资源中心 | D16: 员工管理与发展部 | E16: 员工关系岗 | F16: P2 | G16: 43392 | H16: 胡荣萍
A17: M02101 | B17: 袁杰 | C17: 人力资源中心 | D17: 员工管理与发展部 | E17: 薪酬核算岗 | F17: P1 | G17: 43402 | H17: 胡荣萍
A18: M01894 | B18: 赵玥 | C18: 人力资源中心 | D18: 员工管理与发展部 | E18: 行政文秘岗 | G18: 43259 | H18: 胡荣萍
A19: M01789 | B19: 何慧 | C19: 人力资源中心 | D19: 员工管理与发展部 | E19: 培训管理岗 | F19: P3 | G19: 43201 | H19: 胡荣萍
A20: M01790 | B20: 胡荣萍 | C20: 人力资源中心 | D20: 员工管理与发展部 | E20: 员工发展组负责人 | F20: P4 | G20: 43201 | H20: 于文浩
A21: M01738 | B21: 王永亮 | C21: 人力资源中心 | D21: 薪酬绩效管理部 | E21: 薪酬福利组负责人 | F21: P4 | G21: 43122 | H21: 于文浩
A22: M02132 | B22: 石涛 | C22: 人力资源中心 | D22: 薪酬绩效管理部 | E22: 薪酬管理岗 | F22: P2 | G22: 43437 | H22: 于文浩
A23: M00517 | B23: 高月军 | C23: 人力资源中心 | D23: 薪酬绩效管理部 | E23: 绩效管理岗 | F23: P3 | G23: 42536 | H23: 王永亮
A24: M00197 | B24: 陈晓婕 | C24: 人力资源中心 | D24: 行政管理部 | E24: 采购管理岗 | F24: P3 | G24: 42289 | H24: 于文浩
A25: M01966 | B25: 周华靓 | C25: 人力资源中心 | D25: 行政管理部 | E25: 资产管理岗 | F25: P3 | G25: 43290 | H25: 于文浩
A26: M00231 | B26: 宋李奥贝 | C26: 人力资源中心 | D26: 行政管理部 | E26: 行政总务岗 | F26: P3 | G26: 42324 | H26: 沈治华
A27: M00482 | B27: 张丽 | C27: 人力资源中心 | D27: 行政管理部 | E27: 行政文秘岗 | F27: P1 | G27: 42524 | H27: 沈治华
A28: M01653 | B28: 沈治华 | C28: 人力资源中心 | D28: 行政管理部 | E28: 职场管理组负责人 | F28: P5 | G28: 43003 | H28: 于文浩
A29: M01979 | B29: 陆晓燕 | C29: 人力资源中心 | D29: 行政管理部 | E29: 行政文秘岗 | G29: 43297 | H29: 沈治华
A30: M00542 | B30: 米菊平 | C30: 人力资源中心 | D30: 行政管理部 | E30: 保洁岗 | G30: 42552 | H30: 荣佳丽
A31: M01834 | B31: 刘艳 | C31: 人力资源中心 | D31: 行政管理部 | E31: 行政管理部负责人 | F31: M6 | G31: 43234 | H31: 于文浩

Sheet 内控法务中心
A1: 2019年员工绩效评估结果汇总表 （内控法务中心）
A2: 中心绩效等级： | B2: B
A3: 评估结果校验：
A4: 绩效等级 | B4: S | C4: A | D4: B | E4: C | F4: D
A5: 绩效分布 | B5: =VLOOKUP(B2,等级分布!A:F,2,0) -> 0.1 | C5: =VLOOKUP(B2,等级分布!A:F,3,0) -> 0.2 | D5: =VLOOKUP(B2,等级分布!A:F,4,0) -> 0.3 | E5: =VLOOKUP(B2,等级分布!A:F,5,0) -> 0.2 | F5: =VLOOKUP(B2,等级分布!A:F,6,0) -> 0.2
A6: 评估结果等级分布
A7: 是否符合规则 | B7: =IF(B6<=B5,"是","否") -> 是 | C7: =IF(C6<=C5,"是","否") -> 是 | D7: =IF(D6<=D5,"是","否") -> 是 | E7: =IF(E6<=E5,"是","否") -> 是 | F7: =IF(F6<=F5,"是","否") -> 是
A8: 注：绩效等级比例浮动规则具体见《2019年一季度绩效检视通知》
A9: 员工编码 | B9: 员工姓名 | C9: 所属中心名称 | D9: 二级部门 | E9: 岗位名称 | F9: 职级 | G9: 入职时间 | H9: 直接上级姓名 | I9: 绩效评估得分 （100分制） | J9: 排名组名称 （如xx部门/xx团队） | K9: 绩效排名 （正序，各排名组单独排名） | L9: 绩效等级 （S、A、B、C、D） | M9: 备注 | N9: 序号
A10: M00958 | B10: 吴姣姣 | C10: 内控法务中心 | D10: 内控合规部 | E10: 内控岗 | F10: P4 | G10: 42702 | H10: 韩佳贇
A11: M00003 | B11: 杨淑敏 | C11: 内控法务中心 | D11: 内部审计部 | E11: 内部审计岗 | F11: M7 | G11: 40057 | H11: 韩佳赟
A12: M00396 | B12: 史亚苹 | C12: 内控法务中心 | D12: 内部审计部 | E12: 内部审计岗 | F12: P2 | G12: 42485 | H12: 韩佳赟
A13: M01046 | B13: 方炜 | C13: 内控法务中心 | D13: 法律服务部 | E13: 印章合同档案管理员 | F13: P2 | G13: 42732 | H13: 周志军
A14: M01100 | B14: 李子贡 | C14: 内控法务中心 | D14: 法律服务部 | E14: 法律服务岗 | F14: P3 | G14: 42753 | H14: 周志军
A15: M01576 | B15: 张颖 | C15: 内控法务中心 | D15: 法律服务部 | E15: 境外事务法务 | F15: P3 | G15: 42956 | H15: 周志军
A16: M01785 | B16: 牛和军 | C16: 内控法务中心 | D16: 法律服务部 | E16: 法律服务岗 | F16: P4 | G16: 43199 | H16: 周志军
A17: M01803 | B17: 周柏亨 | C17: 内控法务中心 | D17: 法律服务部 | E17: 法诉岗 | F17: P2 | G17: 43213 | H17: 李子贡
A18: M01856 | B18: 王丽曼 | C18: 内控法务中心 | D18: 法律服务部 | E18: 法律服务岗 | F18: p2 | G18: 43243 | H18: 周志军
A19: M01871 | B19: 陈黎 | C19: 内控法务中心 | D19: 法律服务部 | E19: 法诉岗 | F19: P1 | G19: 43255 | H19: 李子贡
A20: M01424 | B20: 徐大伟 | C20: 内控法务中心 | D20: 法律服务部 | E20: 法律服务岗 | F20: P3 | G20: 42865 | H20: 周志军

Sheet 等级分布
A1: 中心绩效等级 | B1: 个人绩效等级
B2: S | C2: A | D2: B | E2: C | F2: D
A3: S | B3: 0.2 | C3: 0.2 | D3: 0.3 | E3: 0.2 | F3: 0.1
A4: A | B4: 0.15 | C4: 0.2 | D4: 0.35 | E4: 0.2 | F4: 0.1
A5: B | B5: 0.1 | C5: 0.2 | D5: 0.3 | E5: 0.2 | F5: 0.2
A6: C | B6: 0.1 | C6: 0.2 | D6: 0.3 | E6: 0.2 | F6: 0.2
A7: D | B7: 0.1 | C7: 0.2 | D7: 0.3 | E7: 0.2 | F7: 0.2
